Workbook

Sheet Dashboard
B1: PlateLoop survey · results at a glance
B4: =COUNTA(Students_Data!$A$2:$A$1000)+COUNTA(Kitchen_Data!$A$2:$A$1000)+COUNTA(Hospital_Data!$A$2:$A$1000)+COUNTA(Office_Data!$A$2:$A$1000) -> 50 | E4: =COUNTA(Students_Data!$A$2:$A$1000) -> 30 | H4: =COUNTA(Kitchen_Data!$A$2:$A$1000) -> 8 | K4: =COUNTA(Hospital_Data!$A$2:$A$1000) -> 6 | N4: =COUNTA(Office_Data!$A$2:$A$1000) -> 6
B5: responses in total | E5: Students | H5: Kitchen staff | K5: Hospital staff | N5: Office workers
B8: Students
N9: Main reason for leaving food
B10: =INDEX(Students!$B$25:$B$29,MATCH(MAX(Students!$F$25:$F$29),Students!$F$25:$F$29,0)) -> Portion too big | E10: =MAX(Students!$F$25:$F$29) -> 0.43333333 | H10: =Students!$F$48 -> 0.56666667 | K10: =Students!$F$57 -> 3.9666667
B11: top reason for leaving food | E11: chose that reason | H11: prefer food groups to calories | K11: interest in the Loopi pet (out of 5)
B13: → Loopi: rewards the right portion, shows food groups instead of calories, and the pet gives students a reason to scan.
B16: Kitchen staff
N17: How quantities are decided
B18: =Kitchen!$F$17+Kitchen!$F$18 -> 0.625 | E18: =Kitchen!$F$29 -> 0.125 | H18: =Kitchen!$B$24/100 -> 0.2225 | K18: =Kitchen!$G$50 -> 1
B19: plan by experience or headcount | E19: know which dishes come back | H19: of cooked food thrown away (estimate) | K19: want waste shown by dish
B21: → Kitchen dashboard: shows waste by dish and suggests tomorrow’s order from what was eaten, with no forms to fill in.
B24: Hospital staff
N25: When a poor eater is noticed
B26: =Hospital!$G$53 -> 0.16666667 | E26: =Hospital!$B$24 -> 31.333333 | H26: =Hospital!$F$29 -> 0.33333333 | K26: =Hospital!$G$54 -> 1
B27: trust their intake records | E27: minutes a shift on intake records | H27: poor eaters noticed the same day | K27: want automatic intake records
B29: → Loopi Care: records every tray automatically and alerts nurses the same day a patient eats poorly.
B32: Office workers
N33: Share meal data with employer?
B34: =Office!$G$58 -> 0.33333333 | E34: =Office!$F$34+Office!$F$35 -> 0.5 | H34: =Office!$F$40 -> 0.33333333 | K34: =Office!$F$48+Office!$F$49 -> 0.83333333
B35: know the nutrients in their lunch | E35: afternoon energy dip often or daily | H35: would pre-order to skip the queue | K35: want meal data private or anonymous
B37: → Loopi Work: shows the nutrients in each lunch, offers pre-ordering, and keeps meal data private by default.

Sheet Key findings
B1: Key findings
B2: Calculated live from the responses.
B4: Group | C4: Headline | E4: What the survey shows | F4: What PlateLoop does about it
B5: Students | C5: =MAX(Students!$F$25:$F$29) -> 0.43333333 | D5: =C5 -> 0.43333333 | E5: ="The most common reason for leaving food is '"&INDEX(Students!$B$25:$B$29,MATCH(MAX(Students!$F$25:$F$29),Students!$F$25:$F$29,0))&"' ("&TEXT(MAX(Students!$F$25:$F$29),"0%")&"); "&TEXT(Students!$F$34,"0%")&" would take a smaller portion if they could ask easily." -> The most common reason for leaving food is 'Portion too big' (43%); 47% would take a smaller portion if they could ask easily. | F5: The before scan and right-portion rewards in Loopi: a small plate finished counts fully.
B6: Students | C6: =Students!$F$48 -> 0.56666667 | D6: =C6 -> 0.56666667 | E6: ="When seeing what they ate, "&TEXT(Students!$F$48,"0%")&" would rather see food groups and "&TEXT(Students!$F$49,"0%")&" calories." -> When seeing what they ate, 57% would rather see food groups and 10% calories. | F6: Loopi shows food groups by default; calories stay optional.
B7: Students | C7: =Students!$F$57 -> 3.9666667 | D7: =C7/5 -> 0.79333333 | E7: ="Interest in scanning trays to feed a virtual pet averages "&TEXT(Students!$F$57,"0.0")&" out of 5; "&TEXT(Students!$G$57,"0%")&" agree." -> Interest in scanning trays to feed a virtual pet averages 4.0 out of 5; 67% agree. | F7: The Loopi pet as the reason students scan.
B8: Students | C8: =Students!$G$59 -> 0.43333333 | D8: =C8 -> 0.43333333 | E8: =TEXT(Students!$G$59,"0%")&" of students are comfortable with face sign-in." -> 43% of students are comfortable with face sign-in. | F8: Keep the class-and-number alternative; face sign-in stays optional.
B9: Kitchen staff | C9: =Kitchen!$F$17+Kitchen!$F$18 -> 0.625 | D9: =C9 -> 0.625 | E9: =TEXT(Kitchen!$F$17+Kitchen!$F$18,"0%")&" of kitchen staff decide quantities by experience or headcount; "&TEXT(Kitchen!$F$29,"0%")&" know accurately which dishes come back." -> 63% of kitchen staff decide quantities by experience or headcount; 13% know accurately which dishes come back. | F9: Kitchen dashboard: waste by dish and a forecast from real eating data.
B10: Kitchen staff | C10: =Kitchen!$B$24/100 -> 0.2225 | D10: =C10 -> 0.2225 | E10: ="Kitchen staff estimate "&TEXT(Kitchen!$B$24,"0")&"% of cooked food is thrown away and spend "&TEXT(Kitchen!$B$44,"0")&" minutes a day planning quantities." -> Kitchen staff estimate 22% of cooked food is thrown away and spend 32 minutes a day planning quantities. | F10: A suggested order for tomorrow saves planning time and cuts over-preparation.
B11: Kitchen staff | C11: =Kitchen!$G$50 -> 1 | D11: =C11 -> 1 | E11: ="A suggested order is rated useful by "&TEXT(Kitchen!$G$49,"0%")&" and waste by dish by "&TEXT(Kitchen!$G$50,"0%")&"; "&TEXT(Kitchen!$G$52,"0%")&" worry about extra workload." -> A suggested order is rated useful by 75% and waste by dish by 100%; 50% worry about extra workload. | F11: Measurement is automatic: no forms or manual entry for kitchen staff.
B12: Hospital staff | C12: =Hospital!$G$53 -> 0.16666667 | D12: =C12 -> 0.16666667 | E12: =TEXT(Hospital!$G$53,"0%")&" of hospital staff trust their intake records; documenting intake takes "&TEXT(Hospital!$B$24,"0")&" minutes a shift." -> 17% of hospital staff trust their intake records; documenting intake takes 31 minutes a shift. | F12: Loopi Care records every tray automatically.
B13: Hospital staff | C13: =Hospital!$F$29 -> 0.33333333 | D13: =C13 -> 0.33333333 | E13: ="Staff say a patient who stops eating is noticed the same day in "&TEXT(Hospital!$F$29,"0%")&" of cases." -> Staff say a patient who stops eating is noticed the same day in 33% of cases. | F13: Nurse-station alerts after poor meals, the same day.
B14: Hospital staff | C14: =Hospital!$G$54 -> 1 | D14: =C14 -> 1 | E14: ="Automatic intake records are rated useful by "&TEXT(Hospital!$G$54,"0%")&"; "&TEXT(Hospital!$F$46,"0%")&" say patients would benefit from choosing tomorrow’s meals." -> Automatic intake records are rated useful by 100%; 50% say patients would benefit from choosing tomorrow’s meals. | F14: Loopi Care: per-tray intake and patient meal choice.
B15: Office workers | C15: =Office!$F$34+Office!$F$35 -> 0.5 | D15: =C15 -> 0.5 | E15: =TEXT(Office!$G$58,"0%")&" of office workers know the nutrients in their lunch; "&TEXT(Office!$F$34+Office!$F$35,"0%")&" feel an afternoon energy dip often or daily." -> 33% of office workers know the nutrients in their lunch; 50% feel an afternoon energy dip often or daily. | F15: Loopi Work: nutrients per lunch and a 3 pm energy check-in.
B16: Office workers | C16: =Office!$F$40 -> 0.33333333 | D16: =C16 -> 0.33333333 | E16: =TEXT(Office!$F$40,"0%")&" would pre-order lunch to skip a typical "&TEXT(Office!$B$53,"0")&"-minute queue." -> 33% would pre-order lunch to skip a typical 10-minute queue. | F16: Pre-ordering in Loopi Work; kitchens cook to orders.
B17: Office workers | C17: =Office!$F$47 -> 0.16666667 | D17: =C17 -> 0.16666667 | E17: =TEXT(Office!$F$47,"0%")&" would share meal data with their employer; "&TEXT(Office!$F$48,"0%")&" would share anonymous totals only." -> 17% would share meal data with their employer; 50% would share anonymous totals only. | F17: Private by default: employers see team totals, never names.

Sheet Students
B1: Students
B2: =COUNTA(Students_Data!$A$2:$A$1000)&" responses · PlateLoop answer: Loopi" -> 30 responses · PlateLoop answer: Loopi
B4: =INDEX(Students!$B$25:$B$29,MATCH(MAX(Students!$F$25:$F$29),Students!$F$25:$F$29,0)) -> Portion too big | E4: =MAX(Students!$F$25:$F$29) -> 0.43333333 | H4: =Students!$F$48 -> 0.56666667 | K4: =Students!$F$57 -> 3.9666667
B5: top reason for leaving food | E5: chose that reason | H5: prefer food groups to calories | K5: interest in the Loopi pet (out of 5)
B8: S1 · Which are you?
B9: Answer | E9: People | F9: Share
B10: Secondary school | E10: =COUNTIF(Students_Data!$B$2:$B$1000,B10) -> 22 | F10: =IFERROR(E10/SUM($E$10:$E$11),0) -> 0.73333333 | G10: =F10 -> 0.73333333
B11: University | E11: =COUNTIF(Students_Data!$B$2:$B$1000,B11) -> 8 | F11: =IFERROR(E11/SUM($E$10:$E$11),0) -> 0.26666667 | G11: =F11 -> 0.26666667
B14: S2 · How often do you leave food on your tray?
B15: Answer | E15: People | F15: Share
B16: Never | E16: =COUNTIF(Students_Data!$C$2:$C$1000,B16) -> 3 | F16: =IFERROR(E16/SUM($E$16:$E$20),0) -> 0.1 | G16: =F16 -> 0.1
B17: Rarely | E17: =COUNTIF(Students_Data!$C$2:$C$1000,B17) -> 9 | F17: =IFERROR(E17/SUM($E$16:$E$20),0) -> 0.3 | G17: =F17 -> 0.3
B18: Sometimes | E18: =COUNTIF(Students_Data!$C$2:$C$1000,B18) -> 10 | F18: =IFERROR(E18/SUM($E$16:$E$20),0) -> 0.33333333 | G18: =F18 -> 0.33333333
B19: Often | E19: =COUNTIF(Students_Data!$C$2:$C$1000,B19) -> 6 | F19: =IFERROR(E19/SUM($E$16:$E$20),0) -> 0.2 | G19: =F19 -> 0.2
B20: Almost always | E20: =COUNTIF(Students_Data!$C$2:$C$1000,B20) -> 2 | F20: =IFERROR(E20/SUM($E$16:$E$20),0) -> 0.066666667 | G20: =F20 -> 0.066666667
B23: S3 · What is the main reason you leave food?
B24: Answer | E24: People | F24: Share
B25: Portion too big | E25: =COUNTIF(Students_Data!$D$2:$D$1000,B25) -> 13 | F25: =IFERROR(E25/SUM($E$25:$E$29),0) -> 0.43333333 | G25: =F25 -> 0.43333333
B26: Don’t like the taste | E26: =COUNTIF(Students_Data!$D$2:$D$1000,B26) -> 5 | F26: =IFERROR(E26/SUM($E$25:$E$29),0) -> 0.16666667 | G26: =F26 -> 0.16666667
B27: Not hungry | E27: =COUNTIF(Students_Data!$D$2:$D$1000,B27) -> 8 | F27: =IFERROR(E27/SUM($E$25:$E$29),0) -> 0.26666667 | G27: =F27 -> 0.26666667
B28: Ran out of time | E28: =COUNTIF(Students_Data!$D$2:$D$1000,B28) -> 3 | F28: =IFERROR(E28/SUM($E$25:$E$29),0) -> 0.1 | G28: =F28 -> 0.1
B29: Didn’t recognise the dish | E29: =COUNTIF(Students_Data!$D$2:$D$1000,B29) -> 1 | F29: =IFERROR(E29/SUM($E$25:$E$29),0) -> 0.033333333 | G29: =F29 -> 0.033333333
B32: S4 · Would you take a smaller portion if you could ask for one easily?
B33: Answer | E33: People | F33: Share
B34: Yes | E34: =COUNTIF(Students_Data!$E$2:$E$1000,B34) -> 14 | F34: =IFERROR(E34/SUM($E$34:$E$36),0) -> 0.46666667 | G34: =F34 -> 0.46666667
B35: Maybe | E35: =COUNTIF(Students_Data!$E$2:$E$1000,B35) -> 10 | F35: =IFERROR(E35/SUM($E$34:$E$36),0) -> 0.33333333 | G35: =F35 -> 0.33333333
B36: No | E36: =COUNTIF(Students_Data!$E$2:$E$1000,B36) -> 6 | F36: =IFERROR(E36/SUM($E$34:$E$36),0) -> 0.2 | G36: =F36 -> 0.2
B39: S5 · Are you told to finish everything on your plate?
B40: Answer | E40: People | F40: Share
B41: Yes | E41: =COUNTIF(Students_Data!$F$2:$F$1000,B41) -> 11 | F41: =IFERROR(E41/SUM($E$41:$E$43),0) -> 0.36666667 | G41: =F41 -> 0.36666667
B42: Sometimes | E42: =COUNTIF(Students_Data!$F$2:$F$1000,B42) -> 8 | F42: =IFERROR(E42/SUM($E$41:$E$43),0) -> 0.26666667 | G42: =F42 -> 0.26666667
B43: No | E43: =COUNTIF(Students_Data!$F$2:$F$1000,B43) -> 11 | F43: =IFERROR(E43/SUM($E$41:$E$43),0) -> 0.36666667 | G43: =F43 -> 0.36666667
B46: S7 · Which would you rather see about your lunch?
B47: Answer | E47: People | F47: Share
B48: Food groups | E48: =COUNTIF(Students_Data!$H$2:$H$1000,B48) -> 17 | F48: =IFERROR(E48/SUM($E$48:$E$51),0) -> 0.56666667 | G48: =F48 -> 0.56666667
B49: Calories | E49: =COUNTIF(Students_Data!$H$2:$H$1000,B49) -> 3 | F49: =IFERROR(E49/SUM($E$48:$E$51),0) -> 0.1 | G49: =F49 -> 0.1
B50: Both | E50: =COUNTIF(Students_Data!$H$2:$H$1000,B50) -> 7 | F50: =IFERROR(E50/SUM($E$48:$E$51),0) -> 0.23333333 | G50: =F50 -> 0.23333333
B51: Neither | E51: =COUNTIF(Students_Data!$H$2:$H$1000,B51) -> 3 | F51: =IFERROR(E51/SUM($E$48:$E$51),0) -> 0.1 | G51: =F51 -> 0.1
B54: Scale questions · 1 = disagree / not useful, 5 = agree / very useful
B55: Statement | F55: Average | G55: Agree (4–5)
...

Sheet Kitchen
B1: Kitchen staff
B2: =COUNTA(Kitchen_Data!$A$2:$A$1000)&" responses · PlateLoop answer: Kitchen dashboard" -> 8 responses · PlateLoop answer: Kitchen dashboard
B4: =Kitchen!$F$17+Kitchen!$F$18 -> 0.625 | E4: =Kitchen!$F$29 -> 0.125 | H4: =Kitchen!$B$24/100 -> 0.2225 | K4: =Kitchen!$G$50 -> 1
B5: plan by experience or headcount | E5: know which dishes come back | H5: of cooked food thrown away (estimate) | K5: want waste shown by dish
B8: K1 · What is your role?
B9: Answer | E9: People | F9: Share
B10: Canteen operator | E10: =COUNTIF(Kitchen_Data!$B$2:$B$1000,B10) -> 4 | F10: =IFERROR(E10/SUM($E$10:$E$12),0) -> 0.5 | G10: =F10 -> 0.5
B11: Cook | E11: =COUNTIF(Kitchen_Data!$B$2:$B$1000,B11) -> 2 | F11: =IFERROR(E11/SUM($E$10:$E$12),0) -> 0.25 | G11: =F11 -> 0.25
B12: Kitchen assistant | E12: =COUNTIF(Kitchen_Data!$B$2:$B$1000,B12) -> 2 | F12: =IFERROR(E12/SUM($E$10:$E$12),0) -> 0.25 | G12: =F12 -> 0.25
B15: K2 · How do you mainly decide how much to cook each day?
B16: Answer | E16: People | F16: Share
B17: Past experience | E17: =COUNTIF(Kitchen_Data!$C$2:$C$1000,B17) -> 0 | F17: =IFERROR(E17/SUM($E$17:$E$20),0) -> 0 | G17: =F17 -> 0
B18: Headcount × standard portion | E18: =COUNTIF(Kitchen_Data!$C$2:$C$1000,B18) -> 5 | F18: =IFERROR(E18/SUM($E$17:$E$20),0) -> 0.625 | G18: =F18 -> 0.625
B19: Previous day’s leftovers | E19: =COUNTIF(Kitchen_Data!$C$2:$C$1000,B19) -> 2 | F19: =IFERROR(E19/SUM($E$17:$E$20),0) -> 0.25 | G19: =F19 -> 0.25
B20: Written records | E20: =COUNTIF(Kitchen_Data!$C$2:$C$1000,B20) -> 1 | F20: =IFERROR(E20/SUM($E$17:$E$20),0) -> 0.125 | G20: =F20 -> 0.125
B23: K3 · Roughly what percentage of the food you cook is thrown away on a typical day?
B24: =IFERROR(AVERAGE(Kitchen_Data!$D$2:$D$1000),0) -> 22.25 | D24: =IFERROR(MEDIAN(Kitchen_Data!$D$2:$D$1000),0) -> 22.5 | F24: =IFERROR(MIN(Kitchen_Data!$D$2:$D$1000),0) -> 13 | H24: =IFERROR(MAX(Kitchen_Data!$D$2:$D$1000),0) -> 29
B25: Average | D25: Median | F25: Lowest | H25: Highest
B27: K4 · Do you know which dishes come back on trays most?
B28: Answer | E28: People | F28: Share
B29: Yes, accurately | E29: =COUNTIF(Kitchen_Data!$E$2:$E$1000,B29) -> 1 | F29: =IFERROR(E29/SUM($E$29:$E$31),0) -> 0.125 | G29: =F29 -> 0.125
B30: Roughly | E30: =COUNTIF(Kitchen_Data!$E$2:$E$1000,B30) -> 6 | F30: =IFERROR(E30/SUM($E$29:$E$31),0) -> 0.75 | G30: =F30 -> 0.75
B31: No | E31: =COUNTIF(Kitchen_Data!$E$2:$E$1000,B31) -> 1 | F31: =IFERROR(E31/SUM($E$29:$E$31),0) -> 0.125 | G31: =F31 -> 0.125
B34: K5 · How often do you prepare more food than is eaten?
B35: Answer | E35: People | F35: Share
B36: Never | E36: =COUNTIF(Kitchen_Data!$F$2:$F$1000,B36) -> 1 | F36: =IFERROR(E36/SUM($E$36:$E$40),0) -> 0.125 | G36: =F36 -> 0.125
B37: Rarely | E37: =COUNTIF(Kitchen_Data!$F$2:$F$1000,B37) -> 0 | F37: =IFERROR(E37/SUM($E$36:$E$40),0) -> 0 | G37: =F37 -> 0
B38: Weekly | E38: =COUNTIF(Kitchen_Data!$F$2:$F$1000,B38) -> 4 | F38: =IFERROR(E38/SUM($E$36:$E$40),0) -> 0.5 | G38: =F38 -> 0.5
B39: Several times a week | E39: =COUNTIF(Kitchen_Data!$F$2:$F$1000,B39) -> 3 | F39: =IFERROR(E39/SUM($E$36:$E$40),0) -> 0.375 | G39: =F39 -> 0.375
B40: Daily | E40: =COUNTIF(Kitchen_Data!$F$2:$F$1000,B40) -> 0 | F40: =IFERROR(E40/SUM($E$36:$E$40),0) -> 0 | G40: =F40 -> 0
B43: K9 · How many minutes a day do you spend planning orders and quantities?
B44: =IFERROR(AVERAGE(Kitchen_Data!$J$2:$J$1000),0) -> 32.125 | D44: =IFERROR(MEDIAN(Kitchen_Data!$J$2:$J$1000),0) -> 29 | F44: =IFERROR(MIN(Kitchen_Data!$J$2:$J$1000),0) -> 10 | H44: =IFERROR(MAX(Kitchen_Data!$J$2:$J$1000),0) -> 61
B45: Average | D45: Median | F45: Lowest | H45: Highest
B47: Scale questions · 1 = disagree / not useful, 5 = agree / very useful
B48: Statement | F48: Average | G48: Agree (4–5)
B49: K6 A suggested order for tomorrow, based on what was eaten, would be useful. | F49: =IFERROR(AVERAGE(Kitchen_Data!$G$2:$G$1000),0) -> 4 | G49: =IFERROR(COUNTIF(Kitchen_Data!$G$2:$G$1000,">=4")/COUNT(Kitchen_Data!$G$2:$G$1000),0) -> 0.75 | H49: =G49 -> 0.75
B50: K7 Seeing waste broken down by dish would be useful. | F50: =IFERROR(AVERAGE(Kitchen_Data!$H$2:$H$1000),0) -> 4.75 | G50: =IFERROR(COUNTIF(Kitchen_Data!$H$2:$H$1000,">=4")/COUNT(Kitchen_Data!$H$2:$H$1000),0) -> 1 | H50: =G50 -> 1
B51: K8 A monthly carbon report would be useful. | F51: =IFERROR(AVERAGE(Kitchen_Data!$I$2:$I$1000),0) -> 3.625 | G51: =IFERROR(COUNTIF(Kitchen_Data!$I$2:$I$1000,">=4")/COUNT(Kitchen_Data!$I$2:$I$1000),0) -> 0.375 | H51: =G51 -> 0.375
B52: K10 I am worried a new system would add to my workload. | F52: =IFERROR(AVERAGE(Kitchen_Data!$K$2:$K$1000),0) -> 3.5 | G52: =IFERROR(COUNTIF(Kitchen_Data!$K$2:$K$1000,">=4")/COUNT(Kitchen_Data!$K$2:$K$1000),0) -> 0.5 | H52: =G52 -> 0.5

Sheet Hospital
B1: Hospital staff
B2: =COUNTA(Hospital_Data!$A$2:$A$1000)&" responses · PlateLoop answer: Loopi Care" -> 6 responses · PlateLoop answer: Loopi Care
B4: =Hospital!$G$53 -> 0.16666667 | E4: =Hospital!$B$24 -> 31.333333 | H4: =Hospital!$F$29 -> 0.33333333 | K4: =Hospital!$G$54 -> 1
B5: trust their intake records | E5: minutes a shift on intake records | H5: poor eaters noticed the same day | K5: want automatic intake records
B8: H1 · What is your role?
B9: Answer | E9: People | F9: Share
B10: Nurse | E10: =COUNTIF(Hospital_Data!$B$2:$B$1000,B10) -> 4 | F10: =IFERROR(E10/SUM($E$10:$E$12),0) -> 0.66666667 | G10: =F10 -> 0.66666667
B11: Dietitian | E11: =COUNTIF(Hospital_Data!$B$2:$B$1000,B11) -> 2 | F11: =IFERROR(E11/SUM($E$10:$E$12),0) -> 0.33333333 | G11: =F11 -> 0.33333333
B12: Ward manager | E12: =COUNTIF(Hospital_Data!$B$2:$B$1000,B12) -> 0 | F12: =IFERROR(E12/SUM($E$10:$E$12),0) -> 0 | G12: =F12 -> 0
B15: H2 · How is patients’ food intake mainly tracked on your ward?
B16: Answer | E16: People | F16: Share
B17: Food charts | E17: =COUNTIF(Hospital_Data!$C$2:$C$1000,B17) -> 3 | F17: =IFERROR(E17/SUM($E$17:$E$20),0) -> 0.5 | G17: =F17 -> 0.5
B18: Visual estimate | E18: =COUNTIF(Hospital_Data!$C$2:$C$1000,B18) -> 3 | F18: =IFERROR(E18/SUM($E$17:$E$20),0) -> 0.5 | G18: =F18 -> 0.5
B19: Patient report | E19: =COUNTIF(Hospital_Data!$C$2:$C$1000,B19) -> 0 | F19: =IFERROR(E19/SUM($E$17:$E$20),0) -> 0 | G19: =F19 -> 0
B20: Not tracked | E20: =COUNTIF(Hospital_Data!$C$2:$C$1000,B20) -> 0 | F20: =IFERROR(E20/SUM($E$17:$E$20),0) -> 0 | G20: =F20 -> 0
B23: H4 · How many minutes per shift do you spend documenting food intake?
B24: =IFERROR(AVERAGE(Hospital_Data!$E$2:$E$1000),0) -> 31.333333 | D24: =IFERROR(MEDIAN(Hospital_Data!$E$2:$E$1000),0) -> 34.5 | F24: =IFERROR(MIN(Hospital_Data!$E$2:$E$1000),0) -> 15 | H24: =IFERROR(MAX(Hospital_Data!$E$2:$E$1000),0) -> 43
B25: Average | D25: Median | F25: Lowest | H25: Highest
B27: H5 · How quickly is a patient who stops eating usually noticed?
B28: Answer | E28: People | F28: Share
B29: Same day | E29: =COUNTIF(Hospital_Data!$F$2:$F$1000,B29) -> 2 | F29: =IFERROR(E29/SUM($E$29:$E$32),0) -> 0.33333333 | G29: =F29 -> 0.33333333
B30: After 2–3 days | E30: =COUNTIF(Hospital_Data!$F$2:$F$1000,B30) -> 1 | F30: =IFERROR(E30/SUM($E$29:$E$32),0) -> 0.16666667 | G30: =F30 -> 0.16666667
B31: After 4+ days | E31: =COUNTIF(Hospital_Data!$F$2:$F$1000,B31) -> 2 | F31: =IFERROR(E31/SUM($E$29:$E$32),0) -> 0.33333333 | G31: =F31 -> 0.33333333
B32: Often missed | E32: =COUNTIF(Hospital_Data!$F$2:$F$1000,B32) -> 1 | F32: =IFERROR(E32/SUM($E$29:$E$32),0) -> 0.16666667 | G32: =F32 -> 0.16666667
B35: H6 · What is the most common reason patients leave food?
B36: Answer | E36: People | F36: Share
B37: Poor appetite | E37: =COUNTIF(Hospital_Data!$G$2:$G$1000,B37) -> 4 | F37: =IFERROR(E37/SUM($E$37:$E$41),0) -> 0.66666667 | G37: =F37 -> 0.66666667
B38: Taste | E38: =COUNTIF(Hospital_Data!$G$2:$G$1000,B38) -> 0 | F38: =IFERROR(E38/SUM($E$37:$E$41),0) -> 0 | G38: =F38 -> 0
B39: Portion too big | E39: =COUNTIF(Hospital_Data!$G$2:$G$1000,B39) -> 0 | F39: =IFERROR(E39/SUM($E$37:$E$41),0) -> 0 | G39: =F39 -> 0
B40: Too tired | E40: =COUNTIF(Hospital_Data!$G$2:$G$1000,B40) -> 1 | F40: =IFERROR(E40/SUM($E$37:$E$41),0) -> 0.16666667 | G40: =F40 -> 0.16666667
B41: Pain or nausea | E41: =COUNTIF(Hospital_Data!$G$2:$G$1000,B41) -> 1 | F41: =IFERROR(E41/SUM($E$37:$E$41),0) -> 0.16666667 | G41: =F41 -> 0.16666667
B44: H9 · Would patients benefit from choosing their next day’s meals and portion size?
B45: Answer | E45: People | F45: Share
B46: Yes | E46: =COUNTIF(Hospital_Data!$J$2:$J$1000,B46) -> 3 | F46: =IFERROR(E46/SUM($E$46:$E$48),0) -> 0.5 | G46: =F46 -> 0.5
B47: Maybe | E47: =COUNTIF(Hospital_Data!$J$2:$J$1000,B47) -> 3 | F47: =IFERROR(E47/SUM($E$46:$E$48),0) -> 0.5 | G47: =F47 -> 0.5
B48: No | E48: =COUNTIF(Hospital_Data!$J$2:$J$1000,B48) -> 0 | F48: =IFERROR(E48/SUM($E$46:$E$48),0) -> 0 | G48: =F48 -> 0
B51: Scale questions · 1 = disagree / not useful, 5 = agree / very useful
B52: Statement | F52: Average | G52: Agree (4–5)
B53: H3 I am confident our intake records are accurate. | F53: =IFERROR(AVERAGE(Hospital_Data!$D$2:$D$1000),0) -> 2.1666667 | G53: =IFERROR(COUNTIF(Hospital_Data!$D$2:$D$1000,">=4")/COUNT(Hospital_Data!$D$2:$D$1000),0) -> 0.16666667 | H53: =G53 -> 0.16666667
B54: H7 Automatic intake records for every tray would be useful. | F54: =IFERROR(AVERAGE(Hospital_Data!$H$2:$H$1000),0) -> 4.5 | G54: =IFERROR(COUNTIF(Hospital_Data!$H$2:$H$1000,">=4")/COUNT(Hospital_Data!$H$2:$H$1000),0) -> 1 | H54: =G54 -> 1
...

Sheet Office
B1: Office workers
B2: =COUNTA(Office_Data!$A$2:$A$1000)&" responses · PlateLoop answer: Loopi Work" -> 6 responses · PlateLoop answer: Loopi Work
B4: =Office!$G$58 -> 0.33333333 | E4: =Office!$F$34+Office!$F$35 -> 0.5 | H4: =Office!$F$40 -> 0.33333333 | K4: =Office!$F$48+Office!$F$49 -> 0.83333333
B5: know the nutrients in their lunch | E5: afternoon energy dip often or daily | H5: would pre-order to skip the queue | K5: want meal data private or anonymous
B8: O1 · Your age group
B9: Answer | E9: People | F9: Share
B10: 20–29 | E10: =COUNTIF(Office_Data!$B$2:$B$1000,B10) -> 2 | F10: =IFERROR(E10/SUM($E$10:$E$13),0) -> 0.33333333 | G10: =F10 -> 0.33333333
B11: 30–39 | E11: =COUNTIF(Office_Data!$B$2:$B$1000,B11) -> 3 | F11: =IFERROR(E11/SUM($E$10:$E$13),0) -> 0.5 | G11: =F11 -> 0.5
B12: 40–49 | E12: =COUNTIF(Office_Data!$B$2:$B$1000,B12) -> 1 | F12: =IFERROR(E12/SUM($E$10:$E$13),0) -> 0.16666667 | G12: =F12 -> 0.16666667
B13: 50+ | E13: =COUNTIF(Office_Data!$B$2:$B$1000,B13) -> 0 | F13: =IFERROR(E13/SUM($E$10:$E$13),0) -> 0 | G13: =F13 -> 0
B16: O2 · How many days a week do you eat at the office canteen?
B17: =IFERROR(AVERAGE(Office_Data!$C$2:$C$1000),0) -> 4 | D17: =IFERROR(MEDIAN(Office_Data!$C$2:$C$1000),0) -> 4 | F17: =IFERROR(MIN(Office_Data!$C$2:$C$1000),0) -> 2 | H17: =IFERROR(MAX(Office_Data!$C$2:$C$1000),0) -> 5
B18: Average | D18: Median | F18: Lowest | H18: Highest
B20: O3 · Do you have a health goal for your meals?
B21: Answer | E21: People | F21: Share
B22: Lose weight | E22: =COUNTIF(Office_Data!$D$2:$D$1000,B22) -> 0 | F22: =IFERROR(E22/SUM($E$22:$E$26),0) -> 0 | G22: =F22 -> 0
B23: Build muscle | E23: =COUNTIF(Office_Data!$D$2:$D$1000,B23) -> 1 | F23: =IFERROR(E23/SUM($E$22:$E$26),0) -> 0.16666667 | G23: =F23 -> 0.16666667
B24: Steady energy | E24: =COUNTIF(Office_Data!$D$2:$D$1000,B24) -> 2 | F24: =IFERROR(E24/SUM($E$22:$E$26),0) -> 0.33333333 | G24: =F24 -> 0.33333333
B25: Eat balanced | E25: =COUNTIF(Office_Data!$D$2:$D$1000,B25) -> 2 | F25: =IFERROR(E25/SUM($E$22:$E$26),0) -> 0.33333333 | G25: =F25 -> 0.33333333
B26: None | E26: =COUNTIF(Office_Data!$D$2:$D$1000,B26) -> 1 | F26: =IFERROR(E26/SUM($E$22:$E$26),0) -> 0.16666667 | G26: =F26 -> 0.16666667
B29: O5 · How often do you feel an energy dip in the afternoon?
B30: Answer | E30: People | F30: Share
B31: Never | E31: =COUNTIF(Office_Data!$F$2:$F$1000,B31) -> 0 | F31: =IFERROR(E31/SUM($E$31:$E$35),0) -> 0 | G31: =F31 -> 0
B32: Rarely | E32: =COUNTIF(Office_Data!$F$2:$F$1000,B32) -> 1 | F32: =IFERROR(E32/SUM($E$31:$E$35),0) -> 0.16666667 | G32: =F32 -> 0.16666667
B33: Sometimes | E33: =COUNTIF(Office_Data!$F$2:$F$1000,B33) -> 2 | F33: =IFERROR(E33/SUM($E$31:$E$35),0) -> 0.33333333 | G33: =F33 -> 0.33333333
B34: Often | E34: =COUNTIF(Office_Data!$F$2:$F$1000,B34) -> 1 | F34: =IFERROR(E34/SUM($E$31:$E$35),0) -> 0.16666667 | G34: =F34 -> 0.16666667
B35: Daily | E35: =COUNTIF(Office_Data!$F$2:$F$1000,B35) -> 2 | F35: =IFERROR(E35/SUM($E$31:$E$35),0) -> 0.33333333 | G35: =F35 -> 0.33333333
B38: O6 · Would you pre-order lunch to skip the queue?
B39: Answer | E39: People | F39: Share
B40: Yes | E40: =COUNTIF(Office_Data!$G$2:$G$1000,B40) -> 2 | F40: =IFERROR(E40/SUM($E$40:$E$42),0) -> 0.33333333 | G40: =F40 -> 0.33333333
B41: Maybe | E41: =COUNTIF(Office_Data!$G$2:$G$1000,B41) -> 2 | F41: =IFERROR(E41/SUM($E$40:$E$42),0) -> 0.33333333 | G41: =F41 -> 0.33333333
B42: No | E42: =COUNTIF(Office_Data!$G$2:$G$1000,B42) -> 2 | F42: =IFERROR(E42/SUM($E$40:$E$42),0) -> 0.33333333 | G42: =F42 -> 0.33333333
B45: O8 · Would you share your meal data with your employer?
B46: Answer | E46: People | F46: Share
B47: Yes | E47: =COUNTIF(Office_Data!$I$2:$I$1000,B47) -> 1 | F47: =IFERROR(E47/SUM($E$47:$E$49),0) -> 0.16666667 | G47: =F47 -> 0.16666667
B48: Only anonymous totals | E48: =COUNTIF(Office_Data!$I$2:$I$1000,B48) -> 3 | F48: =IFERROR(E48/SUM($E$47:$E$49),0) -> 0.5 | G48: =F48 -> 0.5
B49: No | E49: =COUNTIF(Office_Data!$I$2:$I$1000,B49) -> 2 | F49: =IFERROR(E49/SUM($E$47:$E$49),0) -> 0.33333333 | G49: =F49 -> 0.33333333
B52: O9 · How many minutes do you usually queue at lunch?
B53: =IFERROR(AVERAGE(Office_Data!$J$2:$J$1000),0) -> 9.8333333 | D53: =IFERROR(MEDIAN(Office_Data!$J$2:$J$1000),0) -> 10 | F53: =IFERROR(MIN(Office_Data!$J$2:$J$1000),0) -> 2 | H53: =IFERROR(MAX(Office_Data!$J$2:$J$1000),0) -> 16
B54: Average | D54: Median | F54: Lowest | H54: Highest
...

Sheet Students_Data
A1: ID | B1: S1 Which are you? | C1: S2 How often do you leave food on your tray? | D1: S3 What is the main reason you leave food? | E1: S4 Would you take a smaller portion if you could ask for one easily? | F1: S5 Are you told to finish everything on your plate? | G1: S6 I would like to see what I ate at lunch (food groups and nutrients). (1–5) | H1: S7 Which would you rather see about your lunch? | I1: S8 I would scan my tray before and after lunch if it fed a virtual pet. (1–5) | J1: S9 A weekly class competition on food waste would motivate me. (1–5) | K1: S10 I would be comfortable signing in to a scanner with my face. (1–5) | L1: S11 Anything else about lunch or food waste at your canteen?
A2: S001 | B2: Secondary school | C2: Often | D2: Not hungry | E2: No | F2: Yes | G2: 5 | H2: Calories | I2: 5 | J2: 5 | K2: 5 | L2: I don’t want my name on a leaderboard.
A3: S002 | B3: University | C3: Almost always | D3: Didn’t recognise the dish | E3: Yes | F3: Yes | G3: 4 | H3: Food groups | I3: 3 | J3: 5 | K3: 3 | L3: I would scan my tray if it gave me points.
A4: S003 | B4: Secondary school | C4: Almost always | D4: Portion too big | E4: Yes | F4: Sometimes | G4: 4 | H4: Food groups | I4: 4 | J4: 4 | K4: 4 | L4: I prefer not to use face scanning.
A5: S004 | B5: University | C5: Sometimes | D5: Don’t like the taste | E5: Yes | F5: Sometimes | G5: 4 | H5: Neither | I5: 3 | J5: 5 | K5: 5 | L5: More choice for vegetarians.
A6: S005 | B6: Secondary school | C6: Sometimes | D6: Portion too big | E6: Yes | F6: No | G6: 4 | H6: Both | I6: 4 | J6: 4 | K6: 2 | L6: More choice for vegetarians.
A7: S006 | B7: University | C7: Never | D7: Not hungry | E7: Yes | F7: No | G7: 3 | H7: Food groups | I7: 5 | J7: 4 | K7: 1 | L7: The canteen throws away so much food at the end of the day.
A8: S007 | B8: University | C8: Rarely | D8: Not hungry | E8: Yes | F8: No | G8: 3 | H8: Food groups | I8: 3 | J8: 4 | K8: 4 | L8: Being told to finish everything makes me feel bad.
A9: S008 | B9: Secondary school | C9: Sometimes | D9: Portion too big | E9: No | F9: Yes | G9: 5 | H9: Food groups | I9: 4 | J9: 3 | K9: 3 | L9: Friends would compete if there was a class leaderboard.
A10: S009 | B10: University | C10: Never | D10: Ran out of time | E10: Maybe | F10: Sometimes | G10: 4 | H10: Both | I10: 3 | J10: 5 | K10: 2 | L10: Lunch is too rushed, I only get 20 minutes.
A11: S010 | B11: Secondary school | C11: Often | D11: Portion too big | E11: Yes | F11: No | G11: 4 | H11: Calories | I11: 5 | J11: 3 | K11: 4 | L11: Queues are too long so I rush my food.
A12: S011 | B12: Secondary school | C12: Often | D12: Ran out of time | E12: Yes | F12: No | G12: 4 | H12: Both | I12: 5 | J12: 5 | K12: 4 | L12: Sometimes I don’t know what the dish is.
A13: S012 | B13: Secondary school | C13: Rarely | D13: Not hungry | E13: Maybe | F13: Sometimes | G13: 5 | H13: Food groups | I13: 3 | J13: 5 | K13: 1 | L13: Smaller portions should cost less.
... A31: S030 | B31: Secondary school | C31: Rarely | D31: Not hungry | E31: Maybe | F31: Yes | G31: 3 | H31: Food groups | I31: 3 | J31: 3 | K31: 3 | L31: Being told to finish everything makes me feel bad.

Sheet Kitchen_Data
A1: ID | B1: K1 What is your role? | C1: K2 How do you mainly decide how much to cook each day? | D1: K3 Roughly what percentage of the food you cook is thrown away on a typical day? | E1: K4 Do you know which dishes come back on trays most? | F1: K5 How often do you prepare more food than is eaten? | G1: K6 A suggested order for tomorrow, based on what was eaten, would be useful. (1–5) | H1: K7 Seeing waste broken down by dish would be useful. (1–5) | I1: K8 A monthly carbon report would be useful. (1–5) | J1: K9 How many minutes a day do you spend planning orders and quantities? | K1: K10 I am worried a new system would add to my workload. (1–5) | L1: K11 Anything else?
A2: K001 | B2: Kitchen assistant | C2: Headcount × standard portion | D2: 29 | E2: Roughly | F2: Several times a week | G2: 5 | H2: 4 | I2: 3 | J2: 61 | K2: 4 | L2: A simple screen would be better than an app.
A3: K002 | B3: Cook | C3: Previous day’s leftovers | D3: 23 | E3: Roughly | F3: Several times a week | G3: 4 | H3: 5 | I3: 3 | J3: 41 | K3: 3 | L3: If it saves money the boss will like it.
A4: K003 | B4: Canteen operator | C4: Previous day’s leftovers | D4: 26 | E4: No | F4: Weekly | G4: 3 | H4: 4 | I4: 3 | J4: 10 | K4: 4 | L4: If it saves money the boss will like it.
A5: K004 | B5: Cook | C5: Headcount × standard portion | D5: 19 | E5: Roughly | F5: Weekly | G5: 4 | H5: 5 | I5: 5 | J5: 18 | K5: 3 | L5: We cook the same amount every day regardless of attendance.
A6: K005 | B6: Canteen operator | C6: Written records | D6: 21 | E6: Roughly | F6: Never | G6: 4 | H6: 5 | I6: 4 | J6: 24 | K6: 5 | L6: We cook the same amount every day regardless of attendance.
A7: K006 | B7: Kitchen assistant | C7: Headcount × standard portion | D7: 22 | E7: Roughly | F7: Weekly | G7: 3 | H7: 5 | I7: 3 | J7: 33 | K7: 4 | L7: I don’t have time to fill in forms.
A8: K007 | B8: Canteen operator | C8: Headcount × standard portion | D8: 25 | E8: Yes, accurately | F8: Weekly | G8: 4 | H8: 5 | I8: 5 | J8: 45 | K8: 2 | L8: If it saves money the boss will like it.
A9: K008 | B9: Canteen operator | C9: Headcount × standard portion | D9: 13 | E9: Roughly | F9: Several times a week | G9: 5 | H9: 5 | I9: 3 | J9: 25 | K9: 3 | L9: We cook the same amount every day regardless of attendance.

Sheet Hospital_Data
A1: ID | B1: H1 What is your role? | C1: H2 How is patients’ food intake mainly tracked on your ward? | D1: H3 I am confident our intake records are accurate. (1–5) | E1: H4 How many minutes per shift do you spend documenting food intake? | F1: H5 How quickly is a patient who stops eating usually noticed? | G1: H6 What is the most common reason patients leave food? | H1: H7 Automatic intake records for every tray would be useful. (1–5) | I1: H8 An alert that includes the patient’s reason for not eating would be useful. (1–5) | J1: H9 Would patients benefit from choosing their next day’s meals and portion size? | K1: H10 Anything else?
A2: H001 | B2: Nurse | C2: Food charts | D2: 2 | E2: 32 | F2: After 4+ days | G2: Poor appetite | H2: 5 | I2: 5 | J2: Yes | K2: Patients would like more choice.
A3: H002 | B3: Dietitian | C3: Food charts | D3: 1 | E3: 37 | F3: Often missed | G3: Too tired | H3: 5 | I3: 5 | J3: Yes | K3: Night staff don’t see what was eaten at lunch.
A4: H003 | B4: Nurse | C4: Food charts | D4: 4 | E4: 15 | F4: Same day | G4: Pain or nausea | H4: 4 | I4: 1 | J4: Maybe | K4: Patients would like more choice.
A5: H004 | B5: Nurse | C5: Visual estimate | D5: 2 | E5: 43 | F5: Same day | G5: Poor appetite | H5: 4 | I5: 5 | J5: Maybe | K5: Elderly patients often leave most of their tray.
A6: H005 | B6: Dietitian | C6: Visual estimate | D6: 2 | E6: 19 | F6: After 2–3 days | G6: Poor appetite | H6: 5 | I6: 3 | J6: Maybe | K6: We need to know protein intake for wound healing.
A7: H006 | B7: Nurse | C7: Visual estimate | D7: 2 | E7: 42 | F7: After 4+ days | G7: Poor appetite | H7: 4 | I7: 4 | J7: Yes | K7: Patients would like more choice.

Sheet Office_Data
A1: ID | B1: O1 Your age group | C1: O2 How many days a week do you eat at the office canteen? | D1: O3 Do you have a health goal for your meals? | E1: O4 I know the nutrients in my canteen lunch. (1–5) | F1: O5 How often do you feel an energy dip in the afternoon? | G1: O6 Would you pre-order lunch to skip the queue? | H1: O7 A daily lunch suggestion for my health goal would be useful. (1–5) | I1: O8 Would you share your meal data with your employer? | J1: O9 How many minutes do you usually queue at lunch? | K1: O10 Anything else?
A2: O001 | B2: 30–39 | C2: 5 | D2: Eat balanced | E2: 4 | F2: Often | G2: Maybe | H2: 5 | I2: Yes | J2: 8 | K2: Afternoon slump after noodles.
A3: O002 | B3: 20–29 | C3: 2 | D3: Steady energy | E3: 4 | F3: Daily | G3: Yes | H3: 5 | I3: Only anonymous totals | J3: 14 | K3: Afternoon slump after noodles.
A4: O003 | B4: 30–39 | C4: 4 | D4: Build muscle | E4: 2 | F4: Sometimes | G4: Maybe | H4: 3 | I4: No | J4: 2 | K4: I get sleepy after the noodles.
A5: O004 | B5: 20–29 | C5: 5 | D5: None | E5: 1 | F5: Rarely | G5: No | H5: 4 | I5: Only anonymous totals | J5: 7 | K5: Calorie counts would be nice, optional though.
A6: O005 | B6: 30–39 | C6: 4 | D6: Eat balanced | E6: 1 | F6: Daily | G6: Yes | H6: 4 | I6: No | J6: 12 | K6: I don’t want HR to see what I eat.
A7: O006 | B7: 40–49 | C7: 4 | D7: Steady energy | E7: 3 | F7: Sometimes | G7: No | H7: 1 | I7: Only anonymous totals | J7: 16 | K7: I don’t want HR to see what I eat.

Sheet Questionnaires
B1: Questionnaires
B3: Group | C3: Code | D3: Question | E3: Type | F3: Answers
B4: Students | C4: S1 | D4: Which are you? | E4: Single choice | F4: Secondary school; University
B5: Students | C5: S2 | D5: How often do you leave food on your tray? | E5: Single choice | F5: Never; Rarely; Sometimes; Often; Almost always
B6: Students | C6: S3 | D6: What is the main reason you leave food? | E6: Single choice | F6: Portion too big; Don’t like the taste; Not hungry; Ran out of time; Didn’t recognise the dish
B7: Students | C7: S4 | D7: Would you take a smaller portion if you could ask for one easily? | E7: Single choice | F7: Yes; Maybe; No
B8: Students | C8: S5 | D8: Are you told to finish everything on your plate? | E8: Single choice | F8: Yes; Sometimes; No
B9: Students | C9: S6 | D9: I would like to see what I ate at lunch (food groups and nutrients). | E9: Scale 1–5 | F9: 1 = Strongly disagree … 5 = Strongly agree
B10: Students | C10: S7 | D10: Which would you rather see about your lunch? | E10: Single choice | F10: Food groups; Calories; Both; Neither
B11: Students | C11: S8 | D11: I would scan my tray before and after lunch if it fed a virtual pet. | E11: Scale 1–5 | F11: 1 = Strongly disagree … 5 = Strongly agree
B12: Students | C12: S9 | D12: A weekly class competition on food waste would motivate me. | E12: Scale 1–5 | F12: 1 = Strongly disagree … 5 = Strongly agree
B13: Students | C13: S10 | D13: I would be comfortable signing in to a scanner with my face. | E13: Scale 1–5 | F13: 1 = Strongly disagree … 5 = Strongly agree
B14: Students | C14: S11 | D14: Anything else about lunch or food waste at your canteen? | E14: Open | F14: Free text
... B45: Office workers | C45: O10 | D45: Anything else? | E45: Open | F45: Free text

Sheet About
B1: About this workbook
B3: Dashboard | C3: Headline numbers and one chart per group.
B4: Key findings | C4: Findings written as live formulas, each matched to a PlateLoop feature.
B5: Group sheets | C5: Students, Kitchen, Hospital, Office: every question as a table with in-cell bars, plus charts.
B6: Data sheets | C6: One row per respondent (blue text = input). To add responses, paste them into these tables (same columns, up to row 1000) — every other sheet updates.
B7: Questionnaires | C7: All questions, codes and answer options. Online version: https://8jiwoo.github.io/plateloop/survey/
B8: Scale questions | C8: 1 = strongly disagree / not useful … 5 = strongly agree / very useful. "Agree" = share answering 4 or 5.
