Workbook

Sheet README
A1: PlateLoop survey analysis
A2: DEMO DATA: every response in this workbook is synthetic (randomly generated) to show how the analysis works. These are NOT real survey results.
A4: Sheet | B4: What it contains
A5: Questionnaires | B5: Every question, its code, type and answer options, by group.
A6: Students_Data … Office_Data | B6: One row per respondent (demo). Blue text = input data. Paste real responses here, same columns.
A7: Analysis | B7: Counts, shares, averages and segment comparisons. All formulas: they update when the data changes (rows 2–1000).
A8: Key_Findings | B8: Findings written as formulas from the Analysis sheet, each linked to a PlateLoop feature.
A10: Legend
A11: Blue text | B11: Input data (responses)
A12: Black text | B12: Formulas
A13: Likert questions | B13: 1 = Strongly disagree / Not useful … 5 = Strongly agree / Very useful. "Agree" = share answering 4 or 5.
A14: Demo sample sizes | B14: Students: 120, Kitchen: 24, Hospital: 36, Office: 80 (seed 2026).

Sheet Key_Findings
A1: Key findings (DEMO DATA: synthetic responses, not real results)
A3: # | B3: Group | C3: Finding (calculated from the Analysis sheet) | D3: What it means for PlateLoop
A4: 1 | B4: Students | C4: ="Portion size is the top reason for leaving food: "&TEXT(Analysis!$C$38,"0%")&" chose it, and "&TEXT(Analysis!$C$54,"0%")&" would take a smaller portion if they could ask easily." -> Portion size is the top reason for leaving food: 35% chose it, and 52% would take a smaller portion if they could ask easily. | D4: The before scan and right-portion rewards in Loopi: a small plate finished counts fully.
A5: 2 | B5: Students | C5: ="More students prefer food groups ("&TEXT(Analysis!$C$82,"0%")&") than calories ("&TEXT(Analysis!$C$83,"0%")&") when seeing what they ate." -> More students prefer food groups (44%) than calories (23%) when seeing what they ate. | D5: Loopi shows food groups by default; calories stay optional.
A6: 3 | B6: Students | C6: ="A virtual pet appeals more to secondary students (average "&TEXT(Analysis!$B$417,"0.0")&"/5) than to university students ("&TEXT(Analysis!$B$418,"0.0")&"/5)." -> A virtual pet appeals more to secondary students (average 3.9/5) than to university students (3.5/5). | D6: Lead with the Loopi pet in schools; emphasise nutrition feedback on campuses.
A7: 4 | B7: Students | C7: ="Only "&TEXT(Analysis!$C$100,"0%")&" are comfortable with face sign-in." -> Only 43% are comfortable with face sign-in. | D7: Keep the class-and-number alternative and make face sign-in optional.
A8: 5 | B8: Kitchen | C8: ="Most staff plan by experience or headcount ("&TEXT(Analysis!$C$132+Analysis!$C$133,"0%")&"), and only "&TEXT(Analysis!$C$154,"0%")&" know accurately which dishes come back." -> Most staff plan by experience or headcount (83%), and only 21% know accurately which dishes come back. | D8: Kitchen dashboard: waste by dish and a forecast from real eating data.
A9: 6 | B9: Kitchen | C9: ="Staff estimate "&TEXT(Analysis!$B$146,"0")&"% of cooked food is thrown away, and spend "&TEXT(Analysis!$B$183,"0")&" minutes a day planning quantities." -> Staff estimate 21% of cooked food is thrown away, and spend 34 minutes a day planning quantities. | D9: Tomorrow’s suggested order saves planning time and cuts over-preparation.
A10: 7 | B10: Kitchen | C10: ="A suggested order is rated useful by "&TEXT(Analysis!$C$191,"0%")&" and waste by dish by "&TEXT(Analysis!$C$192,"0%")&", but "&TEXT(Analysis!$C$194,"0%")&" worry about extra workload." -> A suggested order is rated useful by 75% and waste by dish by 67%, but 42% worry about extra workload. | D10: Automatic measurement only: no forms or manual entry for kitchen staff.
A11: 8 | B11: Hospital | C11: ="Only "&TEXT(Analysis!$C$293,"0%")&" of hospital staff trust their intake records, and staff spend "&TEXT(Analysis!$B$240,"0")&" minutes a shift documenting intake." -> Only 22% of hospital staff trust their intake records, and staff spend 30 minutes a shift documenting intake. | D11: Loopi Care records every tray automatically.
A12: 9 | B12: Hospital | C12: ="Patients who stop eating are noticed the same day in only "&TEXT(Analysis!$C$248,"0%")&" of cases." -> Patients who stop eating are noticed the same day in only 14% of cases. | D12: Nurse-station alerts after poor meals, the same day.
A13: 10 | B13: Hospital | C13: ="Automatic intake records are rated useful by "&TEXT(Analysis!$C$294,"0%")&"; "&TEXT(Analysis!$C$279,"0%")&" say patients would benefit from choosing tomorrow’s meals." -> Automatic intake records are rated useful by 83%; 61% say patients would benefit from choosing tomorrow’s meals. | D13: Loopi Care: per-tray intake and patient meal choice.
A14: 11 | B14: Office | C14: ="Only "&TEXT(Analysis!$C$402,"0%")&" of office workers know the nutrients in their lunch, and "&TEXT(Analysis!$C$354+Analysis!$C$355,"0%")&" feel an afternoon energy dip often or daily." -> Only 15% of office workers know the nutrients in their lunch, and 43% feel an afternoon energy dip often or daily. | D14: Loopi Work: nutrients per lunch and a 3 pm energy check-in.
A15: 12 | B15: Office | C15: =TEXT(Analysis!$C$367,"0%")&" would pre-order lunch to skip a typical "&TEXT(Analysis!$B$394,"0")&"-minute queue." -> 64% would pre-order lunch to skip a typical 10-minute queue. | D15: Pre-ordering in Loopi Work; kitchens cook to orders.
A16: 13 | B16: Office | C16: ="Only "&TEXT(Analysis!$C$381,"0%")&" would share meal data with their employer; "&TEXT(Analysis!$C$382,"0%")&" would share anonymous totals only." -> Only 13% would share meal data with their employer; 56% would share anonymous totals only. | D16: Private by default: employers see team totals, never names.

Sheet Questionnaires
A1: Group | B1: Code | C1: Question | D1: Type | E1: Options / scale
A2: Students (secondary school and university) | B2: S1 | C2: Which are you? | D2: Single choice | E2: Secondary school; University
A3: Students (secondary school and university) | B3: S2 | C3: How often do you leave food on your tray? | D3: Single choice | E3: Never; Rarely; Sometimes; Often; Almost always
A4: Students (secondary school and university) | B4: S3 | C4: What is the main reason you leave food? | D4: Single choice | E4: Portion too big; Don’t like the taste; Not hungry; Ran out of time; Didn’t recognise the dish
A5: Students (secondary school and university) | B5: S4 | C5: Would you take a smaller portion if you could ask for one easily? | D5: Single choice | E5: Yes; Maybe; No
A6: Students (secondary school and university) | B6: S5 | C6: Are you told to finish everything on your plate? | D6: Single choice | E6: Yes; Sometimes; No
A7: Students (secondary school and university) | B7: S6 | C7: I would like to see what I ate at lunch (food groups and nutrients). | D7: Scale 1–5 | E7: 1 = Strongly disagree … 5 = Strongly agree
A8: Students (secondary school and university) | B8: S7 | C8: Which would you rather see about your lunch? | D8: Single choice | E8: Food groups; Calories; Both; Neither
A9: Students (secondary school and university) | B9: S8 | C9: I would scan my tray before and after lunch if it fed a virtual pet. | D9: Scale 1–5 | E9: 1 = Strongly disagree … 5 = Strongly agree
A10: Students (secondary school and university) | B10: S9 | C10: A weekly class competition on food waste would motivate me. | D10: Scale 1–5 | E10: 1 = Strongly disagree … 5 = Strongly agree
A11: Students (secondary school and university) | B11: S10 | C11: I would be comfortable signing in to a scanner with my face. | D11: Scale 1–5 | E11: 1 = Strongly disagree … 5 = Strongly agree
A12: Students (secondary school and university) | B12: S11 | C12: Anything else about lunch or food waste at your canteen? | D12: Open | E12: Free text
... A43: Office workers | B43: O10 | C43: Anything else? | D43: Open | E43: Free text

Sheet Students_Data
A1: ID | B1: S1 | C1: S2 | D1: S3 | E1: S4 | F1: S5 | G1: S6 | H1: S7 | I1: S8 | J1: S9 | K1: S10 | L1: S11
A2: S001 | B2: Secondary school | C2: Sometimes | D2: Don’t like the taste | E2: No | F2: Yes | G2: 3 | H2: Calories | I2: 4 | J2: 5 | K2: 3
A3: S002 | B3: University | C3: Often | D3: Don’t like the taste | E3: Yes | F3: No | G3: 2 | H3: Both | I3: 3 | J3: 5 | K3: 4
A4: S003 | B4: Secondary school | C4: Rarely | D4: Didn’t recognise the dish | E4: No | F4: No | G4: 5 | H4: Calories | I4: 2 | J4: 3 | K4: 3 | L4: I prefer not to use face scanning.
A5: S004 | B5: Secondary school | C5: Sometimes | D5: Not hungry | E5: Yes | F5: No | G5: 3 | H5: Calories | I5: 3 | J5: 5 | K5: 3
A6: S005 | B6: Secondary school | C6: Often | D6: Ran out of time | E6: No | F6: Yes | G6: 4 | H6: Both | I6: 4 | J6: 5 | K6: 3
A7: S006 | B7: Secondary school | C7: Often | D7: Ran out of time | E7: No | F7: Sometimes | G7: 4 | H7: Both | I7: 4 | J7: 2 | K7: 5
A8: S007 | B8: Secondary school | C8: Often | D8: Not hungry | E8: Maybe | F8: No | G8: 5 | H8: Food groups | I8: 4 | J8: 5 | K8: 3
A9: S008 | B9: University | C9: Often | D9: Don’t like the taste | E9: Yes | F9: No | G9: 1 | H9: Food groups | I9: 5 | J9: 5 | K9: 4
A10: S009 | B10: Secondary school | C10: Rarely | D10: Not hungry | E10: Yes | F10: Sometimes | G10: 4 | H10: Food groups | I10: 5 | J10: 1 | K10: 2
A11: S010 | B11: University | C11: Sometimes | D11: Not hungry | E11: No | F11: Sometimes | G11: 5 | H11: Food groups | I11: 3 | J11: 5 | K11: 5
A12: S011 | B12: University | C12: Sometimes | D12: Portion too big | E12: No | F12: Sometimes | G12: 5 | H12: Food groups | I12: 3 | J12: 4 | K12: 5
A13: S012 | B13: Secondary school | C13: Rarely | D13: Portion too big | E13: Yes | F13: Yes | G13: 5 | H13: Food groups | I13: 1 | J13: 4 | K13: 4
A14: S013 | B14: University | C14: Often | D14: Didn’t recognise the dish | E14: Yes | F14: No | G14: 2 | H14: Calories | I14: 4 | J14: 3 | K14: 3 | L14: Sometimes I don’t know what the dish is.
A15: S014 | B15: University | C15: Almost always | D15: Portion too big | E15: Yes | F15: No | G15: 4 | H15: Food groups | I15: 1 | J15: 2 | K15: 5 | L15: I don’t want my name on a leaderboard.
A16: S015 | B16: University | C16: Almost always | D16: Didn’t recognise the dish | E16: Yes | F16: No | G16: 4 | H16: Food groups | I16: 5 | J16: 4 | K16: 3
A17: S016 | B17: Secondary school | C17: Sometimes | D17: Portion too big | E17: Maybe | F17: Sometimes | G17: 3 | H17: Both | I17: 4 | J17: 1 | K17: 4 | L17: Being told to finish everything makes me feel bad.
A18: S017 | B18: University | C18: Never | D18: Ran out of time | E18: Maybe | F18: No | G18: 4 | H18: Food groups | I18: 4 | J18: 3 | K18: 5
A19: S018 | B19: Secondary school | C19: Often | D19: Portion too big | E19: Yes | F19: Sometimes | G19: 5 | H19: Food groups | I19: 3 | J19: 3 | K19: 3
A20: S019 | B20: University | C20: Sometimes | D20: Portion too big | E20: Yes | F20: No | G20: 4 | H20: Calories | I20: 3 | J20: 2 | K20: 2 | L20: I would eat more vegetables if they tasted better.
A21: S020 | B21: University | C21: Sometimes | D21: Don’t like the taste | E21: Maybe | F21: No | G21: 4 | H21: Neither | I21: 3 | J21: 2 | K21: 4
A22: S021 | B22: Secondary school | C22: Rarely | D22: Not hungry | E22: Yes | F22: Sometimes | G22: 3 | H22: Food groups | I22: 4 | J22: 4 | K22: 1 | L22: More fruit options please.
A23: S022 | B23: Secondary school | C23: Often | D23: Not hungry | E23: Maybe | F23: Yes | G23: 4 | H23: Calories | I23: 4 | J23: 5 | K23: 2 | L23: A pet game would be fun if it is not too childish.
A24: S023 | B24: Secondary school | C24: Never | D24: Ran out of time | E24: No | F24: Yes | G24: 5 | H24: Food groups | I24: 3 | J24: 3 | K24: 1
A25: S024 | B25: University | C25: Often | D25: Portion too big | E25: Yes | F25: No | G25: 4 | H25: Food groups | I25: 3 | J25: 4 | K25: 4 | L25: I would eat more vegetables if they tasted better.
A26: S025 | B26: University | C26: Often | D26: Not hungry | E26: No | F26: No | G26: 5 | H26: Food groups | I26: 4 | J26: 4 | K26: 1
A27: S026 | B27: Secondary school | C27: Almost always | D27: Not hungry | E27: Yes | F27: Sometimes | G27: 3 | H27: Neither | I27: 4 | J27: 3 | K27: 4
A28: S027 | B28: Secondary school | C28: Sometimes | D28: Portion too big | E28: Yes | F28: Yes | G28: 4 | H28: Both | I28: 1 | J28: 4 | K28: 3 | L28: Queues are too long so I rush my food.
A29: S028 | B29: University | C29: Often | D29: Not hungry | E29: Yes | F29: Yes | G29: 4 | H29: Calories | I29: 3 | J29: 5 | K29: 4 | L29: The rice portion is always too big for me.
A30: S029 | B30: Secondary school | C30: Sometimes | D30: Portion too big | E30: Yes | F30: No | G30: 4 | H30: Both | I30: 4 | J30: 4 | K30: 5
A31: S030 | B31: Secondary school | C31: Sometimes | D31: Not hungry | E31: Yes | F31: Sometimes | G31: 1 | H31: Neither | I31: 4 | J31: 5 | K31: 4
A32: S031 | B32: University | C32: Almost always | D32: Don’t like the taste | E32: No | F32: No | G32: 3 | H32: Both | I32: 3 | J32: 3 | K32: 3
A33: S032 | B33: Secondary school | C33: Sometimes | D33: Not hungry | E33: Maybe | F33: Yes | G33: 4 | H33: Food groups | I33: 5 | J33: 5 | K33: 5
A34: S033 | B34: University | C34: Often | D34: Don’t like the taste | E34: Yes | F34: No | G34: 4 | H34: Food groups | I34: 4 | J34: 5 | K34: 1
A35: S034 | B35: Secondary school | C35: Never | D35: Don’t like the taste | E35: Yes | F35: No | G35: 5 | H35: Both | I35: 5 | J35: 2 | K35: 2 | L35: Being told to finish everything makes me feel bad.
A36: S035 | B36: Secondary school | C36: Never | D36: Don’t like the taste | E36: Maybe | F36: Yes | G36: 3 | H36: Calories | I36: 4 | J36: 5 | K36: 2
A37: S036 | B37: Secondary school | C37: Sometimes | D37: Don’t like the taste | E37: Yes | F37: No | G37: 5 | H37: Neither | I37: 5 | J37: 3 | K37: 3 | L37: Being told to finish everything makes me feel bad.
A38: S037 | B38: Secondary school | C38: Never | D38: Portion too big | E38: Maybe | F38: Sometimes | G38: 5 | H38: Both | I38: 2 | J38: 3 | K38: 3
A39: S038 | B39: Secondary school | C39: Rarely | D39: Portion too big | E39: Yes | F39: No | G39: 2 | H39: Food groups | I39: 4 | J39: 2 | K39: 3
A40: S039 | B40: Secondary school | C40: Rarely | D40: Portion too big | E40: Maybe | F40: No | G40: 3 | H40: Food groups | I40: 5 | J40: 5 | K40: 4 | L40: Queues are too long so I rush my food.
...

Sheet Kitchen_Data
A1: ID | B1: K1 | C1: K2 | D1: K3 | E1: K4 | F1: K5 | G1: K6 | H1: K7 | I1: K8 | J1: K9 | K1: K10 | L1: K11
A2: K001 | B2: Cook | C2: Headcount × standard portion | D2: 19 | E2: No | F2: Weekly | G2: 5 | H2: 3 | I2: 2 | J2: 32 | K2: 2 | L2: We cook the same amount every day regardless of attendance.
A3: K002 | B3: Canteen operator | C3: Past experience | D3: 30 | E3: Roughly | F3: Several times a week | G3: 3 | H3: 4 | I3: 4 | J3: 34 | K3: 5
A4: K003 | B4: Cook | C4: Past experience | D4: 23 | E4: Yes, accurately | F4: Weekly | G4: 5 | H4: 2 | I4: 3 | J4: 36 | K4: 4 | L4: We cook the same amount every day regardless of attendance.
A5: K004 | B5: Cook | C5: Past experience | D5: 23 | E5: No | F5: Weekly | G5: 4 | H5: 4 | I5: 4 | J5: 10 | K5: 3 | L5: Vegetables come back the most.
A6: K005 | B6: Cook | C6: Past experience | D6: 19 | E6: No | F6: Several times a week | G6: 4 | H6: 2 | I6: 3 | J6: 15 | K6: 4
A7: K006 | B7: Cook | C7: Headcount × standard portion | D7: 26 | E7: Yes, accurately | F7: Several times a week | G7: 4 | H7: 4 | I7: 4 | J7: 57 | K7: 5
A8: K007 | B8: Canteen operator | C8: Past experience | D8: 12 | E8: Yes, accurately | F8: Several times a week | G8: 5 | H8: 5 | I8: 5 | J8: 53 | K8: 5
A9: K008 | B9: Cook | C9: Past experience | D9: 19 | E9: No | F9: Rarely | G9: 4 | H9: 5 | I9: 4 | J9: 43 | K9: 2
A10: K009 | B10: Kitchen assistant | C10: Headcount × standard portion | D10: 35 | E10: Roughly | F10: Weekly | G10: 4 | H10: 3 | I10: 2 | J10: 33 | K10: 3
A11: K010 | B11: Kitchen assistant | C11: Headcount × standard portion | D11: 25 | E11: No | F11: Several times a week | G11: 4 | H11: 5 | I11: 3 | J11: 43 | K11: 2 | L11: Soup is always wasted.
A12: K011 | B12: Kitchen assistant | C12: Headcount × standard portion | D12: 26 | E12: No | F12: Daily | G12: 5 | H12: 4 | I12: 4 | J12: 48 | K12: 1 | L12: I don’t have time to fill in forms.
A13: K012 | B13: Canteen operator | C13: Past experience | D13: 5 | E13: No | F13: Several times a week | G13: 5 | H13: 5 | I13: 1 | J13: 42 | K13: 1
A14: K013 | B14: Canteen operator | C14: Written records | D14: 14 | E14: Yes, accurately | F14: Rarely | G14: 3 | H14: 5 | I14: 1 | J14: 27 | K14: 2 | L14: Soup is always wasted.
A15: K014 | B15: Canteen operator | C15: Previous day’s leftovers | D15: 17 | E15: Roughly | F15: Several times a week | G15: 4 | H15: 5 | I15: 3 | J15: 43 | K15: 5 | L15: I don’t have time to fill in forms.
A16: K015 | B16: Cook | C16: Past experience | D16: 19 | E16: No | F16: Weekly | G16: 3 | H16: 3 | I16: 3 | J16: 35 | K16: 3 | L16: We cook the same amount every day regardless of attendance.
A17: K016 | B17: Canteen operator | C17: Past experience | D17: 5 | E17: Roughly | F17: Weekly | G17: 5 | H17: 4 | I17: 2 | J17: 24 | K17: 4
A18: K017 | B18: Kitchen assistant | C18: Previous day’s leftovers | D18: 27 | E18: No | F18: Weekly | G18: 2 | H18: 5 | I18: 4 | J18: 37 | K18: 3
A19: K018 | B19: Kitchen assistant | C19: Written records | D19: 20 | E19: No | F19: Rarely | G19: 5 | H19: 4 | I19: 5 | J19: 10 | K19: 3 | L19: Exam weeks and trips change everything.
A20: K019 | B20: Canteen operator | C20: Past experience | D20: 16 | E20: Roughly | F20: Weekly | G20: 4 | H20: 5 | I20: 3 | J20: 47 | K20: 2 | L20: We cook the same amount every day regardless of attendance.
A21: K020 | B21: Canteen operator | C21: Headcount × standard portion | D21: 26 | E21: Yes, accurately | F21: Rarely | G21: 5 | H21: 1 | I21: 5 | J21: 36 | K21: 2 | L21: Vegetables come back the most.
A22: K021 | B22: Cook | C22: Past experience | D22: 28 | E22: Roughly | F22: Rarely | G22: 1 | H22: 5 | I22: 4 | J22: 45 | K22: 5 | L22: Soup is always wasted.
A23: K022 | B23: Canteen operator | C23: Past experience | D23: 25 | E23: No | F23: Rarely | G23: 3 | H23: 4 | I23: 4 | J23: 16 | K23: 4
A24: K023 | B24: Cook | C24: Past experience | D24: 32 | E24: Roughly | F24: Weekly | G24: 4 | H24: 1 | I24: 3 | J24: 22 | K24: 2
A25: K024 | B25: Cook | C25: Past experience | D25: 20 | E25: No | F25: Weekly | G25: 5 | H25: 3 | I25: 4 | J25: 27 | K25: 4

Sheet Hospital_Data
A1: ID | B1: H1 | C1: H2 | D1: H3 | E1: H4 | F1: H5 | G1: H6 | H1: H7 | I1: H8 | J1: H9 | K1: H10
A2: H001 | B2: Nurse | C2: Food charts | D2: 2 | E2: 21 | F2: Same day | G2: Too tired | H2: 5 | I2: 4 | J2: Yes
A3: H002 | B3: Nurse | C3: Food charts | D3: 1 | E3: 20 | F3: After 2–3 days | G3: Taste | H3: 5 | I3: 5 | J3: Yes
A4: H003 | B4: Nurse | C4: Food charts | D4: 2 | E4: 32 | F4: After 2–3 days | G4: Taste | H4: 5 | I4: 3 | J4: Yes
A5: H004 | B5: Nurse | C5: Food charts | D5: 2 | E5: 13 | F5: After 4+ days | G5: Too tired | H5: 3 | I5: 4 | J5: Yes | K5: Patients would like more choice.
A6: H005 | B6: Nurse | C6: Patient report | D6: 1 | E6: 5 | F6: Often missed | G6: Taste | H6: 4 | I6: 5 | J6: Yes
A7: H006 | B7: Nurse | C7: Food charts | D7: 3 | E7: 42 | F7: After 2–3 days | G7: Portion too big | H7: 5 | I7: 5 | J7: Yes | K7: Patients would like more choice.
A8: H007 | B8: Nurse | C8: Patient report | D8: 2 | E8: 20 | F8: Often missed | G8: Portion too big | H8: 3 | I8: 1 | J8: Maybe
A9: H008 | B9: Dietitian | C9: Food charts | D9: 1 | E9: 42 | F9: After 2–3 days | G9: Taste | H9: 4 | I9: 5 | J9: Maybe | K9: Food charts are filled in at the end of the shift from memory.
A10: H009 | B10: Nurse | C10: Patient report | D10: 4 | E10: 37 | F10: After 2–3 days | G10: Poor appetite | H10: 5 | I10: 3 | J10: Maybe
A11: H010 | B11: Dietitian | C11: Food charts | D11: 2 | E11: 39 | F11: Same day | G11: Taste | H11: 5 | I11: 4 | J11: Maybe | K11: Elderly patients often leave most of their tray.
A12: H011 | B12: Nurse | C12: Food charts | D12: 3 | E12: 37 | F12: After 2–3 days | G12: Poor appetite | H12: 5 | I12: 5 | J12: Yes
A13: H012 | B13: Ward manager | C13: Food charts | D13: 3 | E13: 22 | F13: After 4+ days | G13: Portion too big | H13: 5 | I13: 5 | J13: Maybe | K13: Patients would like more choice.
A14: H013 | B14: Nurse | C14: Visual estimate | D14: 2 | E14: 43 | F14: After 4+ days | G14: Taste | H14: 5 | I14: 3 | J14: Maybe
A15: H014 | B15: Nurse | C15: Food charts | D15: 4 | E15: 35 | F15: Same day | G15: Pain or nausea | H15: 4 | I15: 5 | J15: Yes
A16: H015 | B16: Ward manager | C16: Visual estimate | D16: 3 | E16: 29 | F16: After 4+ days | G16: Poor appetite | H16: 4 | I16: 4 | J16: No
A17: H016 | B17: Nurse | C17: Food charts | D17: 2 | E17: 18 | F17: After 2–3 days | G17: Poor appetite | H17: 4 | I17: 5 | J17: Yes
A18: H017 | B18: Nurse | C18: Food charts | D18: 4 | E18: 37 | F18: Often missed | G18: Poor appetite | H18: 2 | I18: 5 | J18: Yes
A19: H018 | B19: Nurse | C19: Food charts | D19: 3 | E19: 33 | F19: Same day | G19: Taste | H19: 4 | I19: 5 | J19: Yes | K19: Food charts are filled in at the end of the shift from memory.
A20: H019 | B20: Ward manager | C20: Food charts | D20: 3 | E20: 44 | F20: After 2–3 days | G20: Poor appetite | H20: 5 | I20: 5 | J20: Maybe
A21: H020 | B21: Nurse | C21: Patient report | D21: 3 | E21: 35 | F21: After 4+ days | G21: Too tired | H21: 5 | I21: 4 | J21: Maybe | K21: Food charts are filled in at the end of the shift from memory.
A22: H021 | B22: Nurse | C22: Visual estimate | D22: 4 | E22: 17 | F22: After 2–3 days | G22: Poor appetite | H22: 4 | I22: 4 | J22: No
A23: H022 | B23: Nurse | C23: Visual estimate | D23: 3 | E23: 46 | F23: After 4+ days | G23: Too tired | H23: 3 | I23: 4 | J23: Yes
A24: H023 | B24: Nurse | C24: Visual estimate | D24: 3 | E24: 35 | F24: Same day | G24: Portion too big | H24: 5 | I24: 5 | J24: Yes
A25: H024 | B25: Nurse | C25: Patient report | D25: 3 | E25: 40 | F25: After 2–3 days | G25: Taste | H25: 4 | I25: 5 | J25: Maybe
A26: H025 | B26: Nurse | C26: Patient report | D26: 1 | E26: 7 | F26: After 2–3 days | G26: Poor appetite | H26: 4 | I26: 5 | J26: Yes | K26: We need to know protein intake for wound healing.
A27: H026 | B27: Ward manager | C27: Food charts | D27: 3 | E27: 25 | F27: After 2–3 days | G27: Taste | H27: 4 | I27: 4 | J27: Maybe | K27: We need to know protein intake for wound healing.
A28: H027 | B28: Nurse | C28: Food charts | D28: 5 | E28: 5 | F28: After 4+ days | G28: Taste | H28: 4 | I28: 2 | J28: Yes | K28: We need to know protein intake for wound healing.
A29: H028 | B29: Nurse | C29: Food charts | D29: 2 | E29: 41 | F29: After 4+ days | G29: Poor appetite | H29: 5 | I29: 5 | J29: Yes | K29: We need to know protein intake for wound healing.
A30: H029 | B30: Nurse | C30: Food charts | D30: 2 | E30: 32 | F30: After 2–3 days | G30: Portion too big | H30: 5 | I30: 4 | J30: Yes | K30: Patients would like more choice.
A31: H030 | B31: Nurse | C31: Food charts | D31: 3 | E31: 27 | F31: After 2–3 days | G31: Poor appetite | H31: 5 | I31: 5 | J31: Yes | K31: Food charts are filled in at the end of the shift from memory.
A32: H031 | B32: Ward manager | C32: Food charts | D32: 5 | E32: 27 | F32: Often missed | G32: Portion too big | H32: 4 | I32: 5 | J32: Yes | K32: Patients would like more choice.
A33: H032 | B33: Dietitian | C33: Patient report | D33: 4 | E33: 56 | F33: After 4+ days | G33: Pain or nausea | H33: 3 | I33: 3 | J33: Yes
A34: H033 | B34: Nurse | C34: Food charts | D34: 4 | E34: 37 | F34: After 4+ days | G34: Taste | H34: 3 | I34: 5 | J34: No
A35: H034 | B35: Nurse | C35: Food charts | D35: 2 | E35: 40 | F35: After 2–3 days | G35: Portion too big | H35: 4 | I35: 5 | J35: Maybe
A36: H035 | B36: Ward manager | C36: Food charts | D36: 3 | E36: 23 | F36: Often missed | G36: Taste | H36: 5 | I36: 5 | J36: Yes
A37: H036 | B37: Nurse | C37: Visual estimate | D37: 2 | E37: 17 | F37: After 2–3 days | G37: Pain or nausea | H37: 5 | I37: 4 | J37: Yes

Sheet Office_Data
A1: ID | B1: O1 | C1: O2 | D1: O3 | E1: O4 | F1: O5 | G1: O6 | H1: O7 | I1: O8 | J1: O9 | K1: O10
A2: O001 | B2: 30–39 | C2: 5 | D2: Lose weight | E2: 2 | F2: Daily | G2: Maybe | H2: 4 | I2: Only anonymous totals | J2: 9 | K2: Healthy options run out early.
A3: O002 | B3: 30–39 | C3: 4 | D3: Steady energy | E3: 1 | F3: Sometimes | G3: Yes | H3: 5 | I3: No | J3: 5
A4: O003 | B4: 30–39 | C4: 3 | D4: None | E4: 1 | F4: Often | G4: Yes | H4: 3 | I4: Yes | J4: 7
A5: O004 | B5: 30–39 | C5: 3 | D5: Build muscle | E5: 2 | F5: Sometimes | G5: Yes | H5: 5 | I5: Only anonymous totals | J5: 9
A6: O005 | B6: 40–49 | C6: 4 | D6: Build muscle | E6: 2 | F6: Never | G6: No | H6: 5 | I6: Only anonymous totals | J6: 3
A7: O006 | B7: 50+ | C7: 2 | D7: Steady energy | E7: 4 | F7: Daily | G7: Yes | H7: 5 | I7: No | J7: 7 | K7: Pre-ordering would save me 15 minutes.
A8: O007 | B8: 40–49 | C8: 2 | D8: Steady energy | E8: 2 | F8: Sometimes | G8: Yes | H8: 4 | I8: No | J8: 14
A9: O008 | B9: 30–39 | C9: 4 | D9: Lose weight | E9: 1 | F9: Daily | G9: Yes | H9: 3 | I9: No | J9: 2
A10: O009 | B10: 30–39 | C10: 5 | D10: Steady energy | E10: 1 | F10: Often | G10: Yes | H10: 5 | I10: No | J10: 9
A11: O010 | B11: 30–39 | C11: 2 | D11: Lose weight | E11: 5 | F11: Daily | G11: Yes | H11: 3 | I11: Only anonymous totals | J11: 18 | K11: Pre-ordering would save me 15 minutes.
A12: O011 | B12: 30–39 | C12: 5 | D12: Steady energy | E12: 3 | F12: Daily | G12: Yes | H12: 3 | I12: Only anonymous totals | J12: 9
A13: O012 | B13: 50+ | C13: 2 | D13: Eat balanced | E13: 4 | F13: Sometimes | G13: Yes | H13: 4 | I13: Yes | J13: 15
A14: O013 | B14: 50+ | C14: 1 | D14: Eat balanced | E14: 2 | F14: Rarely | G14: Yes | H14: 2 | I14: No | J14: 8 | K14: I don’t want HR to see what I eat.
A15: O014 | B15: 50+ | C15: 4 | D15: None | E15: 2 | F15: Sometimes | G15: No | H15: 4 | I15: Yes | J15: 3
A16: O015 | B16: 20–29 | C16: 5 | D16: Build muscle | E16: 2 | F16: Often | G16: Yes | H16: 4 | I16: Only anonymous totals | J16: 10
A17: O016 | B17: 30–39 | C17: 1 | D17: None | E17: 2 | F17: Sometimes | G17: Yes | H17: 4 | I17: No | J17: 13
A18: O017 | B18: 30–39 | C18: 2 | D18: Lose weight | E18: 3 | F18: Sometimes | G18: Yes | H18: 3 | I18: No | J18: 13 | K18: Afternoon slump after noodles.
A19: O018 | B19: 40–49 | C19: 4 | D19: Steady energy | E19: 1 | F19: Sometimes | G19: Yes | H19: 1 | I19: No | J19: 15
A20: O019 | B20: 30–39 | C20: 5 | D20: Eat balanced | E20: 1 | F20: Often | G20: Yes | H20: 4 | I20: Only anonymous totals | J20: 13
A21: O020 | B21: 40–49 | C21: 3 | D21: Lose weight | E21: 3 | F21: Rarely | G21: No | H21: 4 | I21: No | J21: 9
A22: O021 | B22: 50+ | C22: 4 | D22: Lose weight | E22: 2 | F22: Rarely | G22: No | H22: 5 | I22: Yes | J22: 17
A23: O022 | B23: 20–29 | C23: 2 | D23: Steady energy | E23: 1 | F23: Often | G23: Yes | H23: 3 | I23: No | J23: 13
A24: O023 | B24: 30–39 | C24: 4 | D24: Build muscle | E24: 2 | F24: Often | G24: No | H24: 5 | I24: Only anonymous totals | J24: 12
A25: O024 | B25: 20–29 | C25: 3 | D25: Steady energy | E25: 2 | F25: Daily | G25: Yes | H25: 4 | I25: Only anonymous totals | J25: 3 | K25: Healthy options run out early.
A26: O025 | B26: 40–49 | C26: 4 | D26: Lose weight | E26: 1 | F26: Never | G26: Yes | H26: 3 | I26: Only anonymous totals | J26: 13 | K26: I never know how many calories are in the mixed rice.
A27: O026 | B27: 30–39 | C27: 5 | D27: Build muscle | E27: 2 | F27: Never | G27: Yes | H27: 2 | I27: Only anonymous totals | J27: 13 | K27: I never know how many calories are in the mixed rice.
A28: O027 | B28: 30–39 | C28: 3 | D28: Eat balanced | E28: 1 | F28: Daily | G28: Yes | H28: 4 | I28: No | J28: 6
A29: O028 | B29: 30–39 | C29: 5 | D29: Eat balanced | E29: 3 | F29: Daily | G29: Yes | H29: 4 | I29: No | J29: 15 | K29: Afternoon slump after noodles.
A30: O029 | B30: 40–49 | C30: 4 | D30: Steady energy | E30: 1 | F30: Sometimes | G30: Yes | H30: 4 | I30: Yes | J30: 15
A31: O030 | B31: 20–29 | C31: 2 | D31: Build muscle | E31: 1 | F31: Daily | G31: Yes | H31: 2 | I31: Only anonymous totals | J31: 9
A32: O031 | B32: 50+ | C32: 3 | D32: Lose weight | E32: 2 | F32: Sometimes | G32: Yes | H32: 4 | I32: Only anonymous totals | J32: 6
A33: O032 | B33: 30–39 | C33: 3 | D33: Lose weight | E33: 4 | F33: Daily | G33: Yes | H33: 3 | I33: Only anonymous totals | J33: 3
A34: O033 | B34: 30–39 | C34: 2 | D34: Eat balanced | E34: 1 | F34: Sometimes | G34: Yes | H34: 4 | I34: Yes | J34: 16
A35: O034 | B35: 20–29 | C35: 2 | D35: Lose weight | E35: 3 | F35: Sometimes | G35: No | H35: 4 | I35: No | J35: 11 | K35: Pre-ordering would save me 15 minutes.
A36: O035 | B36: 20–29 | C36: 2 | D36: None | E36: 1 | F36: Sometimes | G36: Maybe | H36: 3 | I36: Only anonymous totals | J36: 12
A37: O036 | B37: 40–49 | C37: 4 | D37: Steady energy | E37: 2 | F37: Rarely | G37: Yes | H37: 4 | I37: Yes | J37: 12
A38: O037 | B38: 40–49 | C38: 3 | D38: None | E38: 1 | F38: Often | G38: Maybe | H38: 4 | I38: Only anonymous totals | J38: 9 | K38: I don’t want HR to see what I eat.
A39: O038 | B39: 40–49 | C39: 3 | D39: Steady energy | E39: 3 | F39: Often | G39: Yes | H39: 4 | I39: No | J39: 11 | K39: I don’t want HR to see what I eat.
A40: O039 | B40: 40–49 | C40: 1 | D40: Lose weight | E40: 1 | F40: Often | G40: Yes | H40: 5 | I40: Only anonymous totals | J40: 7
...

Sheet Analysis
A1: Analysis (DEMO DATA)
A2: All values are formulas over the data sheets (rows 2–1000).
A4: Students (secondary school and university)
A5: Respondents | B5: =COUNTA(Students_Data!$A$2:$A$1000) -> 120
A7: S1 Which are you?
A8: Answer | B8: Count | C8: Share
A9: Secondary school | B9: =COUNTIF(Students_Data!$B$2:$B$1000,A9) -> 68 | C9: =IFERROR(B9/SUM($B$9:$B$10),0) -> 0.56666667
A10: University | B10: =COUNTIF(Students_Data!$B$2:$B$1000,A10) -> 52 | C10: =IFERROR(B10/SUM($B$9:$B$10),0) -> 0.43333333
A20: S2 How often do you leave food on your tray?
A21: Answer | B21: Count | C21: Share
A22: Never | B22: =COUNTIF(Students_Data!$C$2:$C$1000,A22) -> 12 | C22: =IFERROR(B22/SUM($B$22:$B$26),0) -> 0.1
A23: Rarely | B23: =COUNTIF(Students_Data!$C$2:$C$1000,A23) -> 17 | C23: =IFERROR(B23/SUM($B$22:$B$26),0) -> 0.14166667
A24: Sometimes | B24: =COUNTIF(Students_Data!$C$2:$C$1000,A24) -> 42 | C24: =IFERROR(B24/SUM($B$22:$B$26),0) -> 0.35
A25: Often | B25: =COUNTIF(Students_Data!$C$2:$C$1000,A25) -> 32 | C25: =IFERROR(B25/SUM($B$22:$B$26),0) -> 0.26666667
A26: Almost always | B26: =COUNTIF(Students_Data!$C$2:$C$1000,A26) -> 17 | C26: =IFERROR(B26/SUM($B$22:$B$26),0) -> 0.14166667
A36: S3 What is the main reason you leave food?
A37: Answer | B37: Count | C37: Share
A38: Portion too big | B38: =COUNTIF(Students_Data!$D$2:$D$1000,A38) -> 42 | C38: =IFERROR(B38/SUM($B$38:$B$42),0) -> 0.35
A39: Don’t like the taste | B39: =COUNTIF(Students_Data!$D$2:$D$1000,A39) -> 30 | C39: =IFERROR(B39/SUM($B$38:$B$42),0) -> 0.25
A40: Not hungry | B40: =COUNTIF(Students_Data!$D$2:$D$1000,A40) -> 24 | C40: =IFERROR(B40/SUM($B$38:$B$42),0) -> 0.2
A41: Ran out of time | B41: =COUNTIF(Students_Data!$D$2:$D$1000,A41) -> 12 | C41: =IFERROR(B41/SUM($B$38:$B$42),0) -> 0.1
A42: Didn’t recognise the dish | B42: =COUNTIF(Students_Data!$D$2:$D$1000,A42) -> 12 | C42: =IFERROR(B42/SUM($B$38:$B$42),0) -> 0.1
A52: S4 Would you take a smaller portion if you could ask for one easily?
A53: Answer | B53: Count | C53: Share
A54: Yes | B54: =COUNTIF(Students_Data!$E$2:$E$1000,A54) -> 62 | C54: =IFERROR(B54/SUM($B$54:$B$56),0) -> 0.51666667
A55: Maybe | B55: =COUNTIF(Students_Data!$E$2:$E$1000,A55) -> 34 | C55: =IFERROR(B55/SUM($B$54:$B$56),0) -> 0.28333333
A56: No | B56: =COUNTIF(Students_Data!$E$2:$E$1000,A56) -> 24 | C56: =IFERROR(B56/SUM($B$54:$B$56),0) -> 0.2
A66: S5 Are you told to finish everything on your plate?
A67: Answer | B67: Count | C67: Share
A68: Yes | B68: =COUNTIF(Students_Data!$F$2:$F$1000,A68) -> 35 | C68: =IFERROR(B68/SUM($B$68:$B$70),0) -> 0.29166667
A69: Sometimes | B69: =COUNTIF(Students_Data!$F$2:$F$1000,A69) -> 30 | C69: =IFERROR(B69/SUM($B$68:$B$70),0) -> 0.25
A70: No | B70: =COUNTIF(Students_Data!$F$2:$F$1000,A70) -> 55 | C70: =IFERROR(B70/SUM($B$68:$B$70),0) -> 0.45833333
A80: S7 Which would you rather see about your lunch?
A81: Answer | B81: Count | C81: Share
A82: Food groups | B82: =COUNTIF(Students_Data!$H$2:$H$1000,A82) -> 53 | C82: =IFERROR(B82/SUM($B$82:$B$85),0) -> 0.44166667
A83: Calories | B83: =COUNTIF(Students_Data!$H$2:$H$1000,A83) -> 27 | C83: =IFERROR(B83/SUM($B$82:$B$85),0) -> 0.225
A84: Both | B84: =COUNTIF(Students_Data!$H$2:$H$1000,A84) -> 25 | C84: =IFERROR(B84/SUM($B$82:$B$85),0) -> 0.20833333
A85: Neither | B85: =COUNTIF(Students_Data!$H$2:$H$1000,A85) -> 15 | C85: =IFERROR(B85/SUM($B$82:$B$85),0) -> 0.125
A95: Scale questions (1–5)
A96: Question | B96: Average (1–5) | C96: Agree (4–5) | D96: Answers
...
